E
======================================================================
ERROR: test_eval_1 (__main__.TestNetflix)
----------------------------------------------------------------------
Traceback (most recent call last):
  File "TestNetflix.py", line 24, in test_eval_1
    netflix_eval(r, w)
  File "/v/filer4b/v35q001/ras4653/cs329e/cs329e-netflix/Netflix.py", line 107, in netflix_eval
    value = actual_scores_cache[int(current_customer), int(current_movie)]
KeyError: (1417435, 2612)

----------------------------------------------------------------------
Ran 1 test in 1.043s

FAILED (errors=1)
Current Movie 2612
CURRENT CUSTOMER <class 'str'>
IT WORKS! (1581659, 2005) 3.583
3.583
current customer 1581659
current movie 2612
2
CURRENT CUSTOMER <class 'str'>
IT WORKS! (1417435, 2004) 3.564
IT WORKS! (1417435, 2003) 3.261
IT WORKS! (1417435, 2005) 3.654
3.493
current customer 1417435
current movie 2612
